Workbook
Name kpi_fat: Cálculos!$F$5
Name kpi_fat_ant: Cálculos!$F$8
Name kpi_qtd: Cálculos!$F$6
Name kpi_ticket: Cálculos!$F$7
Name kpi_var: Cálculos!$F$9
Name lista_anos: Cálculos!$A$5:$A$13
Name lista_marcas: Cálculos!$C$5:$C$12
Name lista_paises: Cálculos!$B$5:$B$11
Name marca_lider: Cálculos!$N$5
Name modelo_lider: Cálculos!$O$27
Name pais_lider: Cálculos!$N$16
Name sel_ano: Dashboard!$C$5
Name sel_marca: Dashboard!$I$5
Name sel_pais: Dashboard!$F$5

Sheet Dashboard
B1: DASHBOARD DE VENDAS DE VEÍCULOS
B2: Base: 985 vendas de 2013 a jun/2020 · 7 marcas · 54 modelos · 6 países
B5: ANO | C5: Todos | E5: PAÍS | F5: Todos | H5: MARCA | I5: Todas | K5: ◄ Escolha nas listas para filtrar todo o painel
B7: FATURAMENTO | E7: Nº DE VENDAS | H7: TICKET MÉDIO | K7: VS ANO ANTERIOR | N7: MARCA LÍDER | Q7: MODELO LÍDER
B8: =kpi_fat -> 59835220 | E8: =kpi_qtd -> 985 | H8: =kpi_ticket -> 60746.416 | K8: =IF(kpi_var="","—",kpi_var) -> — | N8: =marca_lider -> Honda | Q8: =modelo_lider -> Sandero
K11: =IF(sel_ano="Todos","Selecione um ano para comparar","Comparado com "&(sel_ano-1)) -> Selecione um ano para comparar | N11: ="País líder: "&pais_lider -> País líder: Brasil
B47: TOP 10 MODELOS | M47: COMO LER ESTE PAINEL
B48: # | C48: Modelo | E48: Marca | G48: Vendas | H48: Faturamento | J48: % do total
B49: =IF(Cálculos!P27=0,"",1) -> 1 | C49: =IF(Cálculos!P27=0,"",Cálculos!O27) -> Sandero | E49: =IF(Cálculos!P27=0,"",Cálculos!S27) -> Renault | G49: =IF(Cálculos!P27=0,"",Cálculos!Q27) -> 43 | H49: =IF(Cálculos!P27=0,"",Cálculos!P27) -> 2749726 | J49: =IF(Cálculos!P27=0,"",Cálculos!R27) -> 0.045954974 | M49: • Os filtros de Ano, País e Marca atualizam todos os números e gráficos.
B50: =IF(Cálculos!P28=0,"",2) -> 2 | C50: =IF(Cálculos!P28=0,"",Cálculos!O28) -> Clio | E50: =IF(Cálculos!P28=0,"",Cálculos!S28) -> Renault | G50: =IF(Cálculos!P28=0,"",Cálculos!Q28) -> 37 | H50: =IF(Cálculos!P28=0,"",Cálculos!P28) -> 2291216 | J50: =IF(Cálculos!P28=0,"",Cálculos!R28) -> 0.038292096 | M50: • “Vs ano anterior” e a linha cinza só aparecem com um ano selecionado.
B51: =IF(Cálculos!P29=0,"",3) -> 3 | C51: =IF(Cálculos!P29=0,"",Cálculos!O29) -> Ranger | E51: =IF(Cálculos!P29=0,"",Cálculos!S29) -> Ford | G51: =IF(Cálculos!P29=0,"",Cálculos!Q29) -> 38 | H51: =IF(Cálculos!P29=0,"",Cálculos!P29) -> 2245733 | J51: =IF(Cálculos!P29=0,"",Cálculos!R29) -> 0.037531959 | M51: • A evolução anual respeita País e Marca, mas mostra todos os anos.
B52: =IF(Cálculos!P30=0,"",4) -> 4 | C52: =IF(Cálculos!P30=0,"",Cálculos!O30) -> NSX | E52: =IF(Cálculos!P30=0,"",Cálculos!S30) -> Honda | G52: =IF(Cálculos!P30=0,"",Cálculos!Q30) -> 36 | H52: =IF(Cálculos!P30=0,"",Cálculos!P30) -> 2214212.8 | J52: =IF(Cálculos!P30=0,"",Cálculos!R30) -> 0.037005174 | M52: • 2020 tem dados só até junho: compare com cuidado.
B53: =IF(Cálculos!P31=0,"",5) -> 5 | C53: =IF(Cálculos!P31=0,"",Cálculos!O31) -> Mustang | E53: =IF(Cálculos!P31=0,"",Cálculos!S31) -> Ford | G53: =IF(Cálculos!P31=0,"",Cálculos!Q31) -> 36 | H53: =IF(Cálculos!P31=0,"",Cálculos!P31) -> 2163693 | J53: =IF(Cálculos!P31=0,"",Cálculos!R31) -> 0.03616086 | M53: • Dados fictícios, usados apenas para estudo.
B54: =IF(Cálculos!P32=0,"",6) -> 6 | C54: =IF(Cálculos!P32=0,"",Cálculos!O32) -> Accord | E54: =IF(Cálculos!P32=0,"",Cálculos!S32) -> Honda | G54: =IF(Cálculos!P32=0,"",Cálculos!Q32) -> 33 | H54: =IF(Cálculos!P32=0,"",Cálculos!P32) -> 2028150.1 | J54: =IF(Cálculos!P32=0,"",Cálculos!R32) -> 0.033895591
B55: =IF(Cálculos!P33=0,"",7) -> 7 | C55: =IF(Cálculos!P33=0,"",Cálculos!O33) -> Prisma | E55: =IF(Cálculos!P33=0,"",Cálculos!S33) -> Chevrolet | G55: =IF(Cálculos!P33=0,"",Cálculos!Q33) -> 33 | H55: =IF(Cálculos!P33=0,"",Cálculos!P33) -> 1981776 | J55: =IF(Cálculos!P33=0,"",Cálculos!R33) -> 0.03312056
B56: =IF(Cálculos!P34=0,"",8) -> 8 | C56: =IF(Cálculos!P34=0,"",Cálculos!O34) -> HR-V | E56: =IF(Cálculos!P34=0,"",Cálculos!S34) -> Honda | G56: =IF(Cálculos!P34=0,"",Cálculos!Q34) -> 33 | H56: =IF(Cálculos!P34=0,"",Cálculos!P34) -> 1972500 | J56: =IF(Cálculos!P34=0,"",Cálculos!R34) -> 0.032965534
B57: =IF(Cálculos!P35=0,"",9) -> 9 | C57: =IF(Cálculos!P35=0,"",Cálculos!O35) -> Golf | E57: =IF(Cálculos!P35=0,"",Cálculos!S35) -> Volkswagen | G57: =IF(Cálculos!P35=0,"",Cálculos!Q35) -> 32 | H57: =IF(Cálculos!P35=0,"",Cálculos!P35) -> 1932673 | J57: =IF(Cálculos!P35=0,"",Cálculos!R35) -> 0.032299923
B58: =IF(Cálculos!P36=0,"",10) -> 10 | C58: =IF(Cálculos!P36=0,"",Cálculos!O36) -> Ecosport | E58: =IF(Cálculos!P36=0,"",Cálculos!S36) -> Ford | G58: =IF(Cálculos!P36=0,"",Cálculos!Q36) -> 33 | H58: =IF(Cálculos!P36=0,"",Cálculos!P36) -> 1917430.1 | J58: =IF(Cálculos!P36=0,"",Cálculos!R36) -> 0.032045175

Sheet Base
A1: ID | B1: Data | C1: Ano | D1: Mês | E1: Marca | F1: Modelo | G1: Preço | H1: País | I1: Região | J1: Cliente | K1: Filtro atual | L1: Filtro ano anterior | M1: Filtro sem ano
A2: 938 | B2: 41275 | C2: =YEAR(B2) -> 2013 | D2: =MONTH(B2) -> 1 | E2: Chevrolet | F2: Onix | G2: 74337 | H2: Brasil | I2: Rio Grande do Norte | J2: Olga Stigell | K2: =IF(AND(OR(sel_ano="Todos",C2=sel_ano),OR(sel_pais="Todos",H2=sel_pais),OR(sel_marca="Todas",E2=sel_marca)),1,0) -> 1 | L2: =IF(sel_ano="Todos",0,IF(AND(C2=sel_ano-1,OR(sel_pais="Todos",H2=sel_pais),OR(sel_marca="Todas",E2=sel_marca)),1,0)) -> 0 | M2: =IF(AND(OR(sel_pais="Todos",H2=sel_pais),OR(sel_marca="Todas",E2=sel_marca)),1,0) -> 1
A3: 719 | B3: 41281 | C3: =YEAR(B3) -> 2013 | D3: =MONTH(B3) -> 1 | E3: Volkswagen | F3: Golf | G3: 72987 | H3: Brasil | I3: São Paulo | J3: Jamill Troup | K3: =IF(AND(OR(sel_ano="Todos",C3=sel_ano),OR(sel_pais="Todos",H3=sel_pais),OR(sel_marca="Todas",E3=sel_marca)),1,0) -> 1 | L3: =IF(sel_ano="Todos",0,IF(AND(C3=sel_ano-1,OR(sel_pais="Todos",H3=sel_pais),OR(sel_marca="Todas",E3=sel_marca)),1,0)) -> 0 | M3: =IF(AND(OR(sel_pais="Todos",H3=sel_pais),OR(sel_marca="Todas",E3=sel_marca)),1,0) -> 1
A4: 127 | B4: 41288 | C4: =YEAR(B4) -> 2013 | D4: =MONTH(B4) -> 1 | E4: Honda | F4: NSX | G4: 71014 | H4: Japão | I4: Kyoto | J4: Mychal MacWhirter | K4: =IF(AND(OR(sel_ano="Todos",C4=sel_ano),OR(sel_pais="Todos",H4=sel_pais),OR(sel_marca="Todas",E4=sel_marca)),1,0) -> 1 | L4: =IF(sel_ano="Todos",0,IF(AND(C4=sel_ano-1,OR(sel_pais="Todos",H4=sel_pais),OR(sel_marca="Todas",E4=sel_marca)),1,0)) -> 0 | M4: =IF(AND(OR(sel_pais="Todos",H4=sel_pais),OR(sel_marca="Todas",E4=sel_marca)),1,0) -> 1
A5: 802 | B5: 41294 | C5: =YEAR(B5) -> 2013 | D5: =MONTH(B5) -> 1 | E5: Honda | F5: Accord | G5: 53520 | H5: China | I5: Xangai | J5: Aubrey Rany | K5: =IF(AND(OR(sel_ano="Todos",C5=sel_ano),OR(sel_pais="Todos",H5=sel_pais),OR(sel_marca="Todas",E5=sel_marca)),1,0) -> 1 | L5: =IF(sel_ano="Todos",0,IF(AND(C5=sel_ano-1,OR(sel_pais="Todos",H5=sel_pais),OR(sel_marca="Todas",E5=sel_marca)),1,0)) -> 0 | M5: =IF(AND(OR(sel_pais="Todos",H5=sel_pais),OR(sel_marca="Todas",E5=sel_marca)),1,0) -> 1
A6: 940 | B6: 41296 | C6: =YEAR(B6) -> 2013 | D6: =MONTH(B6) -> 1 | E6: Chevrolet | F6: Prisma | G6: 58157 | H6: Estados Unidos | I6: Washington | J6: Shaylynn Binnie | K6: =IF(AND(OR(sel_ano="Todos",C6=sel_ano),OR(sel_pais="Todos",H6=sel_pais),OR(sel_marca="Todas",E6=sel_marca)),1,0) -> 1 | L6: =IF(sel_ano="Todos",0,IF(AND(C6=sel_ano-1,OR(sel_pais="Todos",H6=sel_pais),OR(sel_marca="Todas",E6=sel_marca)),1,0)) -> 0 | M6: =IF(AND(OR(sel_pais="Todos",H6=sel_pais),OR(sel_marca="Todas",E6=sel_marca)),1,0) -> 1
A7: 230 | B7: 41300 | C7: =YEAR(B7) -> 2013 | D7: =MONTH(B7) -> 1 | E7: Chevrolet | F7: Prisma | G7: 63846 | H7: França | I7: Marselha | J7: Tedie Corden | K7: =IF(AND(OR(sel_ano="Todos",C7=sel_ano),OR(sel_pais="Todos",H7=sel_pais),OR(sel_marca="Todas",E7=sel_marca)),1,0) -> 1 | L7: =IF(sel_ano="Todos",0,IF(AND(C7=sel_ano-1,OR(sel_pais="Todos",H7=sel_pais),OR(sel_marca="Todas",E7=sel_marca)),1,0)) -> 0 | M7: =IF(AND(OR(sel_pais="Todos",H7=sel_pais),OR(sel_marca="Todas",E7=sel_marca)),1,0) -> 1
A8: 776 | B8: 41300 | C8: =YEAR(B8) -> 2013 | D8: =MONTH(B8) -> 1 | E8: BMW | F8: BMW Série 1 | G8: 60167.39 | H8: Estados Unidos | I8: California | J8: Katusha Pluthero | K8: =IF(AND(OR(sel_ano="Todos",C8=sel_ano),OR(sel_pais="Todos",H8=sel_pais),OR(sel_marca="Todas",E8=sel_marca)),1,0) -> 1 | L8: =IF(sel_ano="Todos",0,IF(AND(C8=sel_ano-1,OR(sel_pais="Todos",H8=sel_pais),OR(sel_marca="Todas",E8=sel_marca)),1,0)) -> 0 | M8: =IF(AND(OR(sel_pais="Todos",H8=sel_pais),OR(sel_marca="Todas",E8=sel_marca)),1,0) -> 1
A9: 555 | B9: 41301 | C9: =YEAR(B9) -> 2013 | D9: =MONTH(B9) -> 1 | E9: Volkswagen | F9: Passat | G9: 40937 | H9: China | I9: Pequim | J9: Nara McGahey | K9: =IF(AND(OR(sel_ano="Todos",C9=sel_ano),OR(sel_pais="Todos",H9=sel_pais),OR(sel_marca="Todas",E9=sel_marca)),1,0) -> 1 | L9: =IF(sel_ano="Todos",0,IF(AND(C9=sel_ano-1,OR(sel_pais="Todos",H9=sel_pais),OR(sel_marca="Todas",E9=sel_marca)),1,0)) -> 0 | M9: =IF(AND(OR(sel_pais="Todos",H9=sel_pais),OR(sel_marca="Todas",E9=sel_marca)),1,0) -> 1
A10: 144 | B10: 41302 | C10: =YEAR(B10) -> 2013 | D10: =MONTH(B10) -> 1 | E10: Volkswagen | F10: Voyage | G10: 63467 | H10: França | I10: Lyon | J10: Skippie Doick | K10: =IF(AND(OR(sel_ano="Todos",C10=sel_ano),OR(sel_pais="Todos",H10=sel_pais),OR(sel_marca="Todas",E10=sel_marca)),1,0) -> 1 | L10: =IF(sel_ano="Todos",0,IF(AND(C10=sel_ano-1,OR(sel_pais="Todos",H10=sel_pais),OR(sel_marca="Todas",E10=sel_marca)),1,0)) -> 0 | M10: =IF(AND(OR(sel_pais="Todos",H10=sel_pais),OR(sel_marca="Todas",E10=sel_marca)),1,0) -> 1
A11: 210 | B11: 41302 | C11: =YEAR(B11) -> 2013 | D11: =MONTH(B11) -> 1 | E11: Renault | F11: Clio | G11: 72381 | H11: Brasil | I11: São Paulo | J11: Maynord Lambis | K11: =IF(AND(OR(sel_ano="Todos",C11=sel_ano),OR(sel_pais="Todos",H11=sel_pais),OR(sel_marca="Todas",E11=sel_marca)),1,0) -> 1 | L11: =IF(sel_ano="Todos",0,IF(AND(C11=sel_ano-1,OR(sel_pais="Todos",H11=sel_pais),OR(sel_marca="Todas",E11=sel_marca)),1,0)) -> 0 | M11: =IF(AND(OR(sel_pais="Todos",H11=sel_pais),OR(sel_marca="Todas",E11=sel_marca)),1,0) -> 1
A12: 143 | B12: 41306 | C12: =YEAR(B12) -> 2013 | D12: =MONTH(B12) -> 2 | E12: Ford | F12: Fusion | G12: 47221 | H12: China | I12: Hubei | J12: Emylee Frantsev | K12: =IF(AND(OR(sel_ano="Todos",C12=sel_ano),OR(sel_pais="Todos",H12=sel_pais),OR(sel_marca="Todas",E12=sel_marca)),1,0) -> 1 | L12: =IF(sel_ano="Todos",0,IF(AND(C12=sel_ano-1,OR(sel_pais="Todos",H12=sel_pais),OR(sel_marca="Todas",E12=sel_marca)),1,0)) -> 0 | M12: =IF(AND(OR(sel_pais="Todos",H12=sel_pais),OR(sel_marca="Todas",E12=sel_marca)),1,0) -> 1
A13: 909 | B13: 41310 | C13: =YEAR(B13) -> 2013 | D13: =MONTH(B13) -> 2 | E13: Chevrolet | F13: Spin | G13: 71665 | H13: Argentina | I13: Tucumán | J13: Cherise McKea | K13: =IF(AND(OR(sel_ano="Todos",C13=sel_ano),OR(sel_pais="Todos",H13=sel_pais),OR(sel_marca="Todas",E13=sel_marca)),1,0) -> 1 | L13: =IF(sel_ano="Todos",0,IF(AND(C13=sel_ano-1,OR(sel_pais="Todos",H13=sel_pais),OR(sel_marca="Todas",E13=sel_marca)),1,0)) -> 0 | M13: =IF(AND(OR(sel_pais="Todos",H13=sel_pais),OR(sel_marca="Todas",E13=sel_marca)),1,0) -> 1
... A986: 814 | B986: 44003 | C986: =YEAR(B986) -> 2020 | D986: =MONTH(B986) -> 6 | E986: Ferrari | F986: Portofino | G986: 78443 | H986: Argentina | I986: Mendonza | J986: Horacio Dollard | K986: =IF(AND(OR(sel_ano="Todos",C986=sel_ano),OR(sel_pais="Todos",H986=sel_pais),OR(sel_marca="Todas",E986=sel_marca)),1,0) -> 1 | L986: =IF(sel_ano="Todos",0,IF(AND(C986=sel_ano-1,OR(sel_pais="Todos",H986=sel_pais),OR(sel_marca="Todas",E986=sel_marca)),1,0)) -> 0 | M986: =IF(AND(OR(sel_pais="Todos",H986=sel_pais),OR(sel_marca="Todas",E986=sel_marca)),1,0) -> 1

Sheet Cálculos
A1: Aba de apoio: tudo aqui é calculado a partir da Base e dos filtros do Dashboard.
A3: Listas dos filtros | E3: KPIs | H3: Marcas | M3: Marcas (ordenado)
A4: Anos | B4: Países | C4: Marcas | E4: Indicador | F4: Valor | H4: Item | I4: Faturamento | J4: Vendas | K4: Ajuste | M4: # | N4: Item | O4: Faturamento | P4: Vendas | Q4: % do total
A5: Todos | B5: Todos | C5: Todas | E5: Faturamento | F5: =SUMIFS(Base!$G$2:$G$986,Base!$K$2:$K$986,1) -> 59835220 | H5: BMW | I5: =SUMIFS(Base!$G$2:$G$986,Base!$E$2:$E$986,H5,Base!$K$2:$K$986,1) -> 4548777.6 | J5: =COUNTIFS(Base!$E$2:$E$986,H5,Base!$K$2:$K$986,1) -> 74 | K5: =I5+ROW()/1000000 -> 4548777.6 | M5: 1 | N5: =INDEX($H$5:$H$11,MATCH(LARGE($K$5:$K$11,M5),$K$5:$K$11,0)) -> Honda | O5: =INDEX($I$5:$I$11,MATCH(LARGE($K$5:$K$11,M5),$K$5:$K$11,0)) -> 11766022 | P5: =INDEX($J$5:$J$11,MATCH(LARGE($K$5:$K$11,M5),$K$5:$K$11,0)) -> 196 | Q5: =IFERROR(O5/kpi_fat,0) -> 0.19664041
A6: 2013 | B6: Argentina | C6: BMW | E6: Vendas | F6: =COUNTIFS(Base!$K$2:$K$986,1) -> 985 | H6: Chevrolet | I6: =SUMIFS(Base!$G$2:$G$986,Base!$E$2:$E$986,H6,Base!$K$2:$K$986,1) -> 9647941.1 | J6: =COUNTIFS(Base!$E$2:$E$986,H6,Base!$K$2:$K$986,1) -> 160 | K6: =I6+ROW()/1000000 -> 9647941.1 | M6: 2 | N6: =INDEX($H$5:$H$11,MATCH(LARGE($K$5:$K$11,M6),$K$5:$K$11,0)) -> Ford | O6: =INDEX($I$5:$I$11,MATCH(LARGE($K$5:$K$11,M6),$K$5:$K$11,0)) -> 11688778 | P6: =INDEX($J$5:$J$11,MATCH(LARGE($K$5:$K$11,M6),$K$5:$K$11,0)) -> 193 | Q6: =IFERROR(O6/kpi_fat,0) -> 0.19534946
A7: 2014 | B7: Brasil | C7: Chevrolet | E7: Ticket médio | F7: =IFERROR(kpi_fat/kpi_qtd,0) -> 60746.416 | H7: Ferrari | I7: =SUMIFS(Base!$G$2:$G$986,Base!$E$2:$E$986,H7,Base!$K$2:$K$986,1) -> 3399131 | J7: =COUNTIFS(Base!$E$2:$E$986,H7,Base!$K$2:$K$986,1) -> 55 | K7: =I7+ROW()/1000000 -> 3399131 | M7: 3 | N7: =INDEX($H$5:$H$11,MATCH(LARGE($K$5:$K$11,M7),$K$5:$K$11,0)) -> Renault | O7: =INDEX($I$5:$I$11,MATCH(LARGE($K$5:$K$11,M7),$K$5:$K$11,0)) -> 9733859 | P7: =INDEX($J$5:$J$11,MATCH(LARGE($K$5:$K$11,M7),$K$5:$K$11,0)) -> 157 | Q7: =IFERROR(O7/kpi_fat,0) -> 0.16267775
A8: 2015 | B8: China | C8: Ferrari | E8: Faturamento ano anterior | F8: =SUMIFS(Base!$G$2:$G$986,Base!$L$2:$L$986,1) -> 0 | H8: Ford | I8: =SUMIFS(Base!$G$2:$G$986,Base!$E$2:$E$986,H8,Base!$K$2:$K$986,1) -> 11688778 | J8: =COUNTIFS(Base!$E$2:$E$986,H8,Base!$K$2:$K$986,1) -> 193 | K8: =I8+ROW()/1000000 -> 11688778 | M8: 4 | N8: =INDEX($H$5:$H$11,MATCH(LARGE($K$5:$K$11,M8),$K$5:$K$11,0)) -> Chevrolet | O8: =INDEX($I$5:$I$11,MATCH(LARGE($K$5:$K$11,M8),$K$5:$K$11,0)) -> 9647941.1 | P8: =INDEX($J$5:$J$11,MATCH(LARGE($K$5:$K$11,M8),$K$5:$K$11,0)) -> 160 | Q8: =IFERROR(O8/kpi_fat,0) -> 0.16124184
A9: 2016 | B9: Estados Unidos | C9: Ford | E9: Variação vs ano anterior | F9: =IF(OR(sel_ano="Todos",kpi_fat_ant=0),"",kpi_fat/kpi_fat_ant-1) | H9: Honda | I9: =SUMIFS(Base!$G$2:$G$986,Base!$E$2:$E$986,H9,Base!$K$2:$K$986,1) -> 11766022 | J9: =COUNTIFS(Base!$E$2:$E$986,H9,Base!$K$2:$K$986,1) -> 196 | K9: =I9+ROW()/1000000 -> 11766022 | M9: 5 | N9: =INDEX($H$5:$H$11,MATCH(LARGE($K$5:$K$11,M9),$K$5:$K$11,0)) -> Volkswagen | O9: =INDEX($I$5:$I$11,MATCH(LARGE($K$5:$K$11,M9),$K$5:$K$11,0)) -> 9050711 | P9: =INDEX($J$5:$J$11,MATCH(LARGE($K$5:$K$11,M9),$K$5:$K$11,0)) -> 150 | Q9: =IFERROR(O9/kpi_fat,0) -> 0.1512606
A10: 2017 | B10: França | C10: Honda | H10: Renault | I10: =SUMIFS(Base!$G$2:$G$986,Base!$E$2:$E$986,H10,Base!$K$2:$K$986,1) -> 9733859 | J10: =COUNTIFS(Base!$E$2:$E$986,H10,Base!$K$2:$K$986,1) -> 157 | K10: =I10+ROW()/1000000 -> 9733859 | M10: 6 | N10: =INDEX($H$5:$H$11,MATCH(LARGE($K$5:$K$11,M10),$K$5:$K$11,0)) -> BMW | O10: =INDEX($I$5:$I$11,MATCH(LARGE($K$5:$K$11,M10),$K$5:$K$11,0)) -> 4548777.6 | P10: =INDEX($J$5:$J$11,MATCH(LARGE($K$5:$K$11,M10),$K$5:$K$11,0)) -> 74 | Q10: =IFERROR(O10/kpi_fat,0) -> 0.076021742
A11: 2018 | B11: Japão | C11: Renault | H11: Volkswagen | I11: =SUMIFS(Base!$G$2:$G$986,Base!$E$2:$E$986,H11,Base!$K$2:$K$986,1) -> 9050711 | J11: =COUNTIFS(Base!$E$2:$E$986,H11,Base!$K$2:$K$986,1) -> 150 | K11: =I11+ROW()/1000000 -> 9050711 | M11: 7 | N11: =INDEX($H$5:$H$11,MATCH(LARGE($K$5:$K$11,M11),$K$5:$K$11,0)) -> Ferrari | O11: =INDEX($I$5:$I$11,MATCH(LARGE($K$5:$K$11,M11),$K$5:$K$11,0)) -> 3399131 | P11: =INDEX($J$5:$J$11,MATCH(LARGE($K$5:$K$11,M11),$K$5:$K$11,0)) -> 55 | Q11: =IFERROR(O11/kpi_fat,0) -> 0.056808198
A12: 2019 | C12: Volkswagen
A13: 2020
H14: Países | M14: Países (ordenado)
H15: Item | I15: Faturamento | J15: Vendas | K15: Ajuste | M15: # | N15: Item | O15: Faturamento | P15: Vendas | Q15: % do total
A16: Mensal | H16: Argentina | I16: =SUMIFS(Base!$G$2:$G$986,Base!$H$2:$H$986,H16,Base!$K$2:$K$986,1) -> 7363671.2 | J16: =COUNTIFS(Base!$H$2:$H$986,H16,Base!$K$2:$K$986,1) -> 120 | K16: =I16+ROW()/1000000 -> 7363671.2 | M16: 1 | N16: =INDEX($H$16:$H$21,MATCH(LARGE($K$16:$K$21,M16),$K$16:$K$21,0)) -> Brasil | O16: =INDEX($I$16:$I$21,MATCH(LARGE($K$16:$K$21,M16),$K$16:$K$21,0)) -> 14599392 | P16: =INDEX($J$16:$J$21,MATCH(LARGE($K$16:$K$21,M16),$K$16:$K$21,0)) -> 235 | Q16: =IFERROR(O16/kpi_fat,0) -> 0.24399328
A17: Mês | B17: Período | C17: Ano anterior | D17: Nº mês | H17: Brasil | I17: =SUMIFS(Base!$G$2:$G$986,Base!$H$2:$H$986,H17,Base!$K$2:$K$986,1) -> 14599392 | J17: =COUNTIFS(Base!$H$2:$H$986,H17,Base!$K$2:$K$986,1) -> 235 | K17: =I17+ROW()/1000000 -> 14599392 | M17: 2 | N17: =INDEX($H$16:$H$21,MATCH(LARGE($K$16:$K$21,M17),$K$16:$K$21,0)) -> França | O17: =INDEX($I$16:$I$21,MATCH(LARGE($K$16:$K$21,M17),$K$16:$K$21,0)) -> 11590536 | P17: =INDEX($J$16:$J$21,MATCH(LARGE($K$16:$K$21,M17),$K$16:$K$21,0)) -> 189 | Q17: =IFERROR(O17/kpi_fat,0) -> 0.19370759
A18: Jan | B18: =SUMIFS(Base!$G$2:$G$986,Base!$D$2:$D$986,D18,Base!$K$2:$K$986,1) -> 5767009.4 | C18: =IF(sel_ano="Todos",NA(),SUMIFS(Base!$G$2:$G$986,Base!$D$2:$D$986,D18,Base!$L$2:$L$986,1)) -> #N/A | D18: 1 | H18: China | I18: =SUMIFS(Base!$G$2:$G$986,Base!$H$2:$H$986,H18,Base!$K$2:$K$986,1) -> 10700013 | J18: =COUNTIFS(Base!$H$2:$H$986,H18,Base!$K$2:$K$986,1) -> 181 | K18: =I18+ROW()/1000000 -> 10700013 | M18: 3 | N18: =INDEX($H$16:$H$21,MATCH(LARGE($K$16:$K$21,M18),$K$16:$K$21,0)) -> China | O18: =INDEX($I$16:$I$21,MATCH(LARGE($K$16:$K$21,M18),$K$16:$K$21,0)) -> 10700013 | P18: =INDEX($J$16:$J$21,MATCH(LARGE($K$16:$K$21,M18),$K$16:$K$21,0)) -> 181 | Q18: =IFERROR(O18/kpi_fat,0) -> 0.17882466
A19: Fev | B19: =SUMIFS(Base!$G$2:$G$986,Base!$D$2:$D$986,D19,Base!$K$2:$K$986,1) -> 4726110 | C19: =IF(sel_ano="Todos",NA(),SUMIFS(Base!$G$2:$G$986,Base!$D$2:$D$986,D19,Base!$L$2:$L$986,1)) -> #N/A | D19: 2 | H19: Estados Unidos | I19: =SUMIFS(Base!$G$2:$G$986,Base!$H$2:$H$986,H19,Base!$K$2:$K$986,1) -> 7992626.7 | J19: =COUNTIFS(Base!$H$2:$H$986,H19,Base!$K$2:$K$986,1) -> 131 | K19: =I19+ROW()/1000000 -> 7992626.7 | M19: 4 | N19: =INDEX($H$16:$H$21,MATCH(LARGE($K$16:$K$21,M19),$K$16:$K$21,0)) -> Estados Unidos | O19: =INDEX($I$16:$I$21,MATCH(LARGE($K$16:$K$21,M19),$K$16:$K$21,0)) -> 7992626.7 | P19: =INDEX($J$16:$J$21,MATCH(LARGE($K$16:$K$21,M19),$K$16:$K$21,0)) -> 131 | Q19: =IFERROR(O19/kpi_fat,0) -> 0.13357729
A20: Mar | B20: =SUMIFS(Base!$G$2:$G$986,Base!$D$2:$D$986,D20,Base!$K$2:$K$986,1) -> 3504368.3 | C20: =IF(sel_ano="Todos",NA(),SUMIFS(Base!$G$2:$G$986,Base!$D$2:$D$986,D20,Base!$L$2:$L$986,1)) -> #N/A | D20: 3 | H20: França | I20: =SUMIFS(Base!$G$2:$G$986,Base!$H$2:$H$986,H20,Base!$K$2:$K$986,1) -> 11590536 | J20: =COUNTIFS(Base!$H$2:$H$986,H20,Base!$K$2:$K$986,1) -> 189 | K20: =I20+ROW()/1000000 -> 11590536 | M20: 5 | N20: =INDEX($H$16:$H$21,MATCH(LARGE($K$16:$K$21,M20),$K$16:$K$21,0)) -> Japão | O20: =INDEX($I$16:$I$21,MATCH(LARGE($K$16:$K$21,M20),$K$16:$K$21,0)) -> 7588981.3 | P20: =INDEX($J$16:$J$21,MATCH(LARGE($K$16:$K$21,M20),$K$16:$K$21,0)) -> 129 | Q20: =IFERROR(O20/kpi_fat,0) -> 0.12683134
A21: Abr | B21: =SUMIFS(Base!$G$2:$G$986,Base!$D$2:$D$986,D21,Base!$K$2:$K$986,1) -> 4926338 | C21: =IF(sel_ano="Todos",NA(),SUMIFS(Base!$G$2:$G$986,Base!$D$2:$D$986,D21,Base!$L$2:$L$986,1)) -> #N/A | D21: 4 | H21: Japão | I21: =SUMIFS(Base!$G$2:$G$986,Base!$H$2:$H$986,H21,Base!$K$2:$K$986,1) -> 7588981.3 | J21: =COUNTIFS(Base!$H$2:$H$986,H21,Base!$K$2:$K$986,1) -> 129 | K21: =I21+ROW()/1000000 -> 7588981.3 | M21: 6 | N21: =INDEX($H$16:$H$21,MATCH(LARGE($K$16:$K$21,M21),$K$16:$K$21,0)) -> Argentina | O21: =INDEX($I$16:$I$21,MATCH(LARGE($K$16:$K$21,M21),$K$16:$K$21,0)) -> 7363671.2 | P21: =INDEX($J$16:$J$21,MATCH(LARGE($K$16:$K$21,M21),$K$16:$K$21,0)) -> 120 | Q21: =IFERROR(O21/kpi_fat,0) -> 0.12306583
A22: Mai | B22: =SUMIFS(Base!$G$2:$G$986,Base!$D$2:$D$986,D22,Base!$K$2:$K$986,1) -> 5236553.8 | C22: =IF(sel_ano="Todos",NA(),SUMIFS(Base!$G$2:$G$986,Base!$D$2:$D$986,D22,Base!$L$2:$L$986,1)) -> #N/A | D22: 5
A23: Jun | B23: =SUMIFS(Base!$G$2:$G$986,Base!$D$2:$D$986,D23,Base!$K$2:$K$986,1) -> 4704102.8 | C23: =IF(sel_ano="Todos",NA(),SUMIFS(Base!$G$2:$G$986,Base!$D$2:$D$986,D23,Base!$L$2:$L$986,1)) -> #N/A | D23: 6
A24: Jul | B24: =SUMIFS(Base!$G$2:$G$986,Base!$D$2:$D$986,D24,Base!$K$2:$K$986,1) -> 5653561.5 | C24: =IF(sel_ano="Todos",NA(),SUMIFS(Base!$G$2:$G$986,Base!$D$2:$D$986,D24,Base!$L$2:$L$986,1)) -> #N/A | D24: 7
A25: Ago | B25: =SUMIFS(Base!$G$2:$G$986,Base!$D$2:$D$986,D25,Base!$K$2:$K$986,1) -> 5349954.8 | C25: =IF(sel_ano="Todos",NA(),SUMIFS(Base!$G$2:$G$986,Base!$D$2:$D$986,D25,Base!$L$2:$L$986,1)) -> #N/A | D25: 8 | H25: Modelos | N25: Modelos (ordenado)
A26: Set | B26: =SUMIFS(Base!$G$2:$G$986,Base!$D$2:$D$986,D26,Base!$K$2:$K$986,1) -> 4235811 | C26: =IF(sel_ano="Todos",NA(),SUMIFS(Base!$G$2:$G$986,Base!$D$2:$D$986,D26,Base!$L$2:$L$986,1)) -> #N/A | D26: 9 | H26: Item | I26: Faturamento | J26: Vendas | K26: Ajuste | L26: Marca | N26: # | O26: Item | P26: Faturamento | Q26: Vendas | R26: % do total | S26: Marca
A27: Out | B27: =SUMIFS(Base!$G$2:$G$986,Base!$D$2:$D$986,D27,Base!$K$2:$K$986,1) -> 4582455 | C27: =IF(sel_ano="Todos",NA(),SUMIFS(Base!$G$2:$G$986,Base!$D$2:$D$986,D27,Base!$L$2:$L$986,1)) -> #N/A | D27: 10 | H27: 308 GTS | I27: =SUMIFS(Base!$G$2:$G$986,Base!$F$2:$F$986,H27,Base!$K$2:$K$986,1) -> 387954 | J27: =COUNTIFS(Base!$F$2:$F$986,H27,Base!$K$2:$K$986,1) -> 6 | K27: =I27+ROW()/1000000 -> 387954 | L27: Ferrari | N27: 1 | O27: =INDEX($H$27:$H$80,MATCH(LARGE($K$27:$K$80,N27),$K$27:$K$80,0)) -> Sandero | P27: =INDEX($I$27:$I$80,MATCH(LARGE($K$27:$K$80,N27),$K$27:$K$80,0)) -> 2749726 | Q27: =INDEX($J$27:$J$80,MATCH(LARGE($K$27:$K$80,N27),$K$27:$K$80,0)) -> 43 | R27: =IFERROR(P27/kpi_fat,0) -> 0.045954974 | S27: =INDEX($L$27:$L$80,MATCH(LARGE($K$27:$K$80,N27),$K$27:$K$80,0)) -> Renault
A28: Nov | B28: =SUMIFS(Base!$G$2:$G$986,Base!$D$2:$D$986,D28,Base!$K$2:$K$986,1) -> 5057183.9 | C28: =IF(sel_ano="Todos",NA(),SUMIFS(Base!$G$2:$G$986,Base!$D$2:$D$986,D28,Base!$L$2:$L$986,1)) -> #N/A | D28: 11 | H28: 488 | I28: =SUMIFS(Base!$G$2:$G$986,Base!$F$2:$F$986,H28,Base!$K$2:$K$986,1) -> 259632 | J28: =COUNTIFS(Base!$F$2:$F$986,H28,Base!$K$2:$K$986,1) -> 5 | K28: =I28+ROW()/1000000 -> 259632 | L28: Ferrari | N28: 2 | O28: =INDEX($H$27:$H$80,MATCH(LARGE($K$27:$K$80,N28),$K$27:$K$80,0)) -> Clio | P28: =INDEX($I$27:$I$80,MATCH(LARGE($K$27:$K$80,N28),$K$27:$K$80,0)) -> 2291216 | Q28: =INDEX($J$27:$J$80,MATCH(LARGE($K$27:$K$80,N28),$K$27:$K$80,0)) -> 37 | R28: =IFERROR(P28/kpi_fat,0) -> 0.038292096 | S28: =INDEX($L$27:$L$80,MATCH(LARGE($K$27:$K$80,N28),$K$27:$K$80,0)) -> Renault
A29: Dez | B29: =SUMIFS(Base!$G$2:$G$986,Base!$D$2:$D$986,D29,Base!$K$2:$K$986,1) -> 6091771.5 | C29: =IF(sel_ano="Todos",NA(),SUMIFS(Base!$G$2:$G$986,Base!$D$2:$D$986,D29,Base!$L$2:$L$986,1)) -> #N/A | D29: 12 | H29: Accord | I29: =SUMIFS(Base!$G$2:$G$986,Base!$F$2:$F$986,H29,Base!$K$2:$K$986,1) -> 2028150.1 | J29: =COUNTIFS(Base!$F$2:$F$986,H29,Base!$K$2:$K$986,1) -> 33 | K29: =I29+ROW()/1000000 -> 2028150.1 | L29: Honda | N29: 3 | O29: =INDEX($H$27:$H$80,MATCH(LARGE($K$27:$K$80,N29),$K$27:$K$80,0)) -> Ranger | P29: =INDEX($I$27:$I$80,MATCH(LARGE($K$27:$K$80,N29),$K$27:$K$80,0)) -> 2245733 | Q29: =INDEX($J$27:$J$80,MATCH(LARGE($K$27:$K$80,N29),$K$27:$K$80,0)) -> 38 | R29: =IFERROR(P29/kpi_fat,0) -> 0.037531959 | S29: =INDEX($L$27:$L$80,MATCH(LARGE($K$27:$K$80,N29),$K$27:$K$80,0)) -> Ford
H30: BMW Série 1 | I30: =SUMIFS(Base!$G$2:$G$986,Base!$F$2:$F$986,H30,Base!$K$2:$K$986,1) -> 762131.21 | J30: =COUNTIFS(Base!$F$2:$F$986,H30,Base!$K$2:$K$986,1) -> 12 | K30: =I30+ROW()/1000000 -> 762131.21 | L30: BMW | N30: 4 | O30: =INDEX($H$27:$H$80,MATCH(LARGE($K$27:$K$80,N30),$K$27:$K$80,0)) -> NSX | P30: =INDEX($I$27:$I$80,MATCH(LARGE($K$27:$K$80,N30),$K$27:$K$80,0)) -> 2214212.8 | Q30: =INDEX($J$27:$J$80,MATCH(LARGE($K$27:$K$80,N30),$K$27:$K$80,0)) -> 36 | R30: =IFERROR(P30/kpi_fat,0) -> 0.037005174 | S30: =INDEX($L$27:$L$80,MATCH(LARGE($K$27:$K$80,N30),$K$27:$K$80,0)) -> Honda
H31: BMW Série 3 | I31: =SUMIFS(Base!$G$2:$G$986,Base!$F$2:$F$986,H31,Base!$K$2:$K$986,1) -> 418774 | J31: =COUNTIFS(Base!$F$2:$F$986,H31,Base!$K$2:$K$986,1) -> 7 | K31: =I31+ROW()/1000000 -> 418774 | L31: BMW | N31: 5 | O31: =INDEX($H$27:$H$80,MATCH(LARGE($K$27:$K$80,N31),$K$27:$K$80,0)) -> Mustang | P31: =INDEX($I$27:$I$80,MATCH(LARGE($K$27:$K$80,N31),$K$27:$K$80,0)) -> 2163693 | Q31: =INDEX($J$27:$J$80,MATCH(LARGE($K$27:$K$80,N31),$K$27:$K$80,0)) -> 36 | R31: =IFERROR(P31/kpi_fat,0) -> 0.03616086 | S31: =INDEX($L$27:$L$80,MATCH(LARGE($K$27:$K$80,N31),$K$27:$K$80,0)) -> Ford
A32: Anual (ignora filtro de ano) | H32: BMW Série 5 | I32: =SUMIFS(Base!$G$2:$G$986,Base!$F$2:$F$986,H32,Base!$K$2:$K$986,1) -> 320788 | J32: =COUNTIFS(Base!$F$2:$F$986,H32,Base!$K$2:$K$986,1) -> 5 | K32: =I32+ROW()/1000000 -> 320788 | L32: BMW | N32: 6 | O32: =INDEX($H$27:$H$80,MATCH(LARGE($K$27:$K$80,N32),$K$27:$K$80,0)) -> Accord | P32: =INDEX($I$27:$I$80,MATCH(LARGE($K$27:$K$80,N32),$K$27:$K$80,0)) -> 2028150.1 | Q32: =INDEX($J$27:$J$80,MATCH(LARGE($K$27:$K$80,N32),$K$27:$K$80,0)) -> 33 | R32: =IFERROR(P32/kpi_fat,0) -> 0.033895591 | S32: =INDEX($L$27:$L$80,MATCH(LARGE($K$27:$K$80,N32),$K$27:$K$80,0)) -> Honda
A33: Ano | B33: Faturamento | C33: Vendas | H33: CR-V | I33: =SUMIFS(Base!$G$2:$G$986,Base!$F$2:$F$986,H33,Base!$K$2:$K$986,1) -> 1530281 | J33: =COUNTIFS(Base!$F$2:$F$986,H33,Base!$K$2:$K$986,1) -> 26 | K33: =I33+ROW()/1000000 -> 1530281 | L33: Honda | N33: 7 | O33: =INDEX($H$27:$H$80,MATCH(LARGE($K$27:$K$80,N33),$K$27:$K$80,0)) -> Prisma | P33: =INDEX($I$27:$I$80,MATCH(LARGE($K$27:$K$80,N33),$K$27:$K$80,0)) -> 1981776 | Q33: =INDEX($J$27:$J$80,MATCH(LARGE($K$27:$K$80,N33),$K$27:$K$80,0)) -> 33 | R33: =IFERROR(P33/kpi_fat,0) -> 0.03312056 | S33: =INDEX($L$27:$L$80,MATCH(LARGE($K$27:$K$80,N33),$K$27:$K$80,0)) -> Chevrolet
A34: 2013 | B34: =SUMIFS(Base!$G$2:$G$986,Base!$C$2:$C$986,2013,Base!$M$2:$M$986,1) -> 7116424.6 | C34: =COUNTIFS(Base!$C$2:$C$986,2013,Base!$M$2:$M$986,1) -> 115 | H34: Camaro | I34: =SUMIFS(Base!$G$2:$G$986,Base!$F$2:$F$986,H34,Base!$K$2:$K$986,1) -> 1453308.3 | J34: =COUNTIFS(Base!$F$2:$F$986,H34,Base!$K$2:$K$986,1) -> 23 | K34: =I34+ROW()/1000000 -> 1453308.3 | L34: Chevrolet | N34: 8 | O34: =INDEX($H$27:$H$80,MATCH(LARGE($K$27:$K$80,N34),$K$27:$K$80,0)) -> HR-V | P34: =INDEX($I$27:$I$80,MATCH(LARGE($K$27:$K$80,N34),$K$27:$K$80,0)) -> 1972500 | Q34: =INDEX($J$27:$J$80,MATCH(LARGE($K$27:$K$80,N34),$K$27:$K$80,0)) -> 33 | R34: =IFERROR(P34/kpi_fat,0) -> 0.032965534 | S34: =INDEX($L$27:$L$80,MATCH(LARGE($K$27:$K$80,N34),$K$27:$K$80,0)) -> Honda
A35: 2014 | B35: =SUMIFS(Base!$G$2:$G$986,Base!$C$2:$C$986,2014,Base!$M$2:$M$986,1) -> 7841789.3 | C35: =COUNTIFS(Base!$C$2:$C$986,2014,Base!$M$2:$M$986,1) -> 128 | H35: City | I35: =SUMIFS(Base!$G$2:$G$986,Base!$F$2:$F$986,H35,Base!$K$2:$K$986,1) -> 1554147.3 | J35: =COUNTIFS(Base!$F$2:$F$986,H35,Base!$K$2:$K$986,1) -> 27 | K35: =I35+ROW()/1000000 -> 1554147.3 | L35: Honda | N35: 9 | O35: =INDEX($H$27:$H$80,MATCH(LARGE($K$27:$K$80,N35),$K$27:$K$80,0)) -> Golf | P35: =INDEX($I$27:$I$80,MATCH(LARGE($K$27:$K$80,N35),$K$27:$K$80,0)) -> 1932673 | Q35: =INDEX($J$27:$J$80,MATCH(LARGE($K$27:$K$80,N35),$K$27:$K$80,0)) -> 32 | R35: =IFERROR(P35/kpi_fat,0) -> 0.032299923 | S35: =INDEX($L$27:$L$80,MATCH(LARGE($K$27:$K$80,N35),$K$27:$K$80,0)) -> Volkswagen
A36: 2015 | B36: =SUMIFS(Base!$G$2:$G$986,Base!$C$2:$C$986,2015,Base!$M$2:$M$986,1) -> 7666331.3 | C36: =COUNTIFS(Base!$C$2:$C$986,2015,Base!$M$2:$M$986,1) -> 127 | H36: Civic | I36: =SUMIFS(Base!$G$2:$G$986,Base!$F$2:$F$986,H36,Base!$K$2:$K$986,1) -> 657166 | J36: =COUNTIFS(Base!$F$2:$F$986,H36,Base!$K$2:$K$986,1) -> 10 | K36: =I36+ROW()/1000000 -> 657166 | L36: Honda | N36: 10 | O36: =INDEX($H$27:$H$80,MATCH(LARGE($K$27:$K$80,N36),$K$27:$K$80,0)) -> Ecosport | P36: =INDEX($I$27:$I$80,MATCH(LARGE($K$27:$K$80,N36),$K$27:$K$80,0)) -> 1917430.1 | Q36: =INDEX($J$27:$J$80,MATCH(LARGE($K$27:$K$80,N36),$K$27:$K$80,0)) -> 33 | R36: =IFERROR(P36/kpi_fat,0) -> 0.032045175 | S36: =INDEX($L$27:$L$80,MATCH(LARGE($K$27:$K$80,N36),$K$27:$K$80,0)) -> Ford
A37: 2016 | B37: =SUMIFS(Base!$G$2:$G$986,Base!$C$2:$C$986,2016,Base!$M$2:$M$986,1) -> 7811610.2 | C37: =COUNTIFS(Base!$C$2:$C$986,2016,Base!$M$2:$M$986,1) -> 130 | H37: Clio | I37: =SUMIFS(Base!$G$2:$G$986,Base!$F$2:$F$986,H37,Base!$K$2:$K$986,1) -> 2291216 | J37: =COUNTIFS(Base!$F$2:$F$986,H37,Base!$K$2:$K$986,1) -> 37 | K37: =I37+ROW()/1000000 -> 2291216 | L37: Renault | N37: 11 | O37: =INDEX($H$27:$H$80,MATCH(LARGE($K$27:$K$80,N37),$K$27:$K$80,0)) -> Fusion | P37: =INDEX($I$27:$I$80,MATCH(LARGE($K$27:$K$80,N37),$K$27:$K$80,0)) -> 1755800 | Q37: =INDEX($J$27:$J$80,MATCH(LARGE($K$27:$K$80,N37),$K$27:$K$80,0)) -> 30 | R37: =IFERROR(P37/kpi_fat,0) -> 0.029343922 | S37: =INDEX($L$27:$L$80,MATCH(LARGE($K$27:$K$80,N37),$K$27:$K$80,0)) -> Ford
A38: 2017 | B38: =SUMIFS(Base!$G$2:$G$986,Base!$C$2:$C$986,2017,Base!$M$2:$M$986,1) -> 8604811 | C38: =COUNTIFS(Base!$C$2:$C$986,2017,Base!$M$2:$M$986,1) -> 145 | H38: Cruze | I38: =SUMIFS(Base!$G$2:$G$986,Base!$F$2:$F$986,H38,Base!$K$2:$K$986,1) -> 1153550 | J38: =COUNTIFS(Base!$F$2:$F$986,H38,Base!$K$2:$K$986,1) -> 20 | K38: =I38+ROW()/1000000 -> 1153550 | L38: Chevrolet | N38: 12 | O38: =INDEX($H$27:$H$80,MATCH(LARGE($K$27:$K$80,N38),$K$27:$K$80,0)) -> City | P38: =INDEX($I$27:$I$80,MATCH(LARGE($K$27:$K$80,N38),$K$27:$K$80,0)) -> 1554147.3 | Q38: =INDEX($J$27:$J$80,MATCH(LARGE($K$27:$K$80,N38),$K$27:$K$80,0)) -> 27 | R38: =IFERROR(P38/kpi_fat,0) -> 0.025973788 | S38: =INDEX($L$27:$L$80,MATCH(LARGE($K$27:$K$80,N38),$K$27:$K$80,0)) -> Honda
A39: 2018 | B39: =SUMIFS(Base!$G$2:$G$986,Base!$C$2:$C$986,2018,Base!$M$2:$M$986,1) -> 8957729.8 | C39: =COUNTIFS(Base!$C$2:$C$986,2018,Base!$M$2:$M$986,1) -> 146 | H39: Dino 246 | I39: =SUMIFS(Base!$G$2:$G$986,Base!$F$2:$F$986,H39,Base!$K$2:$K$986,1) -> 551437.94 | J39: =COUNTIFS(Base!$F$2:$F$986,H39,Base!$K$2:$K$986,1) -> 10 | K39: =I39+ROW()/1000000 -> 551437.94 | L39: Ferrari | N39: 13 | O39: =INDEX($H$27:$H$80,MATCH(LARGE($K$27:$K$80,N39),$K$27:$K$80,0)) -> CR-V | P39: =INDEX($I$27:$I$80,MATCH(LARGE($K$27:$K$80,N39),$K$27:$K$80,0)) -> 1530281 | Q39: =INDEX($J$27:$J$80,MATCH(LARGE($K$27:$K$80,N39),$K$27:$K$80,0)) -> 26 | R39: =IFERROR(P39/kpi_fat,0) -> 0.025574921 | S39: =INDEX($L$27:$L$80,MATCH(LARGE($K$27:$K$80,N39),$K$27:$K$80,0)) -> Honda
A40: 2019 | B40: =SUMIFS(Base!$G$2:$G$986,Base!$C$2:$C$986,2019,Base!$M$2:$M$986,1) -> 8527353 | C40: =COUNTIFS(Base!$C$2:$C$986,2019,Base!$M$2:$M$986,1) -> 141 | H40: Duster | I40: =SUMIFS(Base!$G$2:$G$986,Base!$F$2:$F$986,H40,Base!$K$2:$K$986,1) -> 1183829 | J40: =COUNTIFS(Base!$F$2:$F$986,H40,Base!$K$2:$K$986,1) -> 20 | K40: =I40+ROW()/1000000 -> 1183829 | L40: Renault | N40: 14 | O40: =INDEX($H$27:$H$80,MATCH(LARGE($K$27:$K$80,N40),$K$27:$K$80,0)) -> Onix | P40: =INDEX($I$27:$I$80,MATCH(LARGE($K$27:$K$80,N40),$K$27:$K$80,0)) -> 1521354 | Q40: =INDEX($J$27:$J$80,MATCH(LARGE($K$27:$K$80,N40),$K$27:$K$80,0)) -> 24 | R40: =IFERROR(P40/kpi_fat,0) -> 0.025425728 | S40: =INDEX($L$27:$L$80,MATCH(LARGE($K$27:$K$80,N40),$K$27:$K$80,0)) -> Chevrolet
A41: 2020 | B41: =SUMIFS(Base!$G$2:$G$986,Base!$C$2:$C$986,2020,Base!$M$2:$M$986,1) -> 3309171 | C41: =COUNTIFS(Base!$C$2:$C$986,2020,Base!$M$2:$M$986,1) -> 53 | H41: Ecosport | I41: =SUMIFS(Base!$G$2:$G$986,Base!$F$2:$F$986,H41,Base!$K$2:$K$986,1) -> 1917430.1 | J41: =COUNTIFS(Base!$F$2:$F$986,H41,Base!$K$2:$K$986,1) -> 33 | K41: =I41+ROW()/1000000 -> 1917430.1 | L41: Ford | N41: 15 | O41: =INDEX($H$27:$H$80,MATCH(LARGE($K$27:$K$80,N41),$K$27:$K$80,0)) -> Voyage | P41: =INDEX($I$27:$I$80,MATCH(LARGE($K$27:$K$80,N41),$K$27:$K$80,0)) -> 1484900 | Q41: =INDEX($J$27:$J$80,MATCH(LARGE($K$27:$K$80,N41),$K$27:$K$80,0)) -> 25 | R41: =IFERROR(P41/kpi_fat,0) -> 0.024816488 | S41: =INDEX($L$27:$L$80,MATCH(LARGE($K$27:$K$80,N41),$K$27:$K$80,0)) -> Volkswagen
...
